# C# 中的异常处理

> 原文:[https://www . tutorial stearner . com/cs harp/cs harp-异常处理](https://www.tutorialsteacher.com/csharp/csharp-exception-handling)

在这里，您将使用 try、catch 和 finally 块了解 C# 中的异常处理。

必须处理应用程序中的异常，以防止程序崩溃和意外结果，记录异常并继续其他功能。C# 提供内置支持，使用`try`、`catch`、& `finally`块处理异常。

Syntax:

```
try
{
    // put the code here that may raise exceptions
}
catch
{
    // handle exception here
}
finally
{
    // final cleanup code
}

```

**试块:**任何可能引发异常的可疑代码都应该放在`try{ }`块中。在执行过程中，如果发生异常，控制流程跳转到第一个匹配的`catch`块。

**catch 块:**`catch`块是一个异常处理程序块，您可以在其中执行一些操作，例如记录和审核异常。`catch`块接受异常类型的参数，使用该参数可以获得异常的详细信息。

**最后一个块:**`finally`块将始终被执行，无论是否引发异常。通常，`finally`块应该用于释放资源，例如，关闭在`try`块中打开的任何流或文件对象。

如果输入非数字字符，下面的内容可能会引发异常。

Example: C# Program

```
class Program
{
    static void Main(string[] args)
    {
        Console.WriteLine("Enter a number: ");

        var num = int.Parse(Console.ReadLine());

        Console.WriteLine($"Squre of {num} is {num * num}");
    }
} 
```

为了处理上面例子中可能出现的异常，将代码包装在`try`块中，并在`catch`块中处理异常，如下所示。

Example: Exception handling using try-catch blocks

```
class Program
{
    static void Main(string[] args)
    {
        try
        {
            Console.WriteLine("Enter a number: ");

            var num = int.parse(Console.ReadLine());

            Console.WriteLine($"Squre of {num} is {num * num}");
        }
        catch
        {
            Console.Write("Error occurred.");
        }
        finally
        {
            Console.Write("Re-try with a different number.");
        }
    }
} 
```

在上面的例子中，我们将这段代码包装在一个`try`块中。如果在`try`块内出现异常，那么程序将跳转到`catch`块。 在`catch`块中，我们显示一条消息来指示用户他的错误，而在`finally`块中，我们显示一条消息来指示运行程序后该做什么。

*Note:**A `try` block must be followed by `catch` or `finally` or both blocks. The `try` block without a `catch` or `finally` block will give a compile-time error.* *理想情况下，`catch`块应该包含一个内置或自定义异常类的参数来获取错误细节。以下包括捕获所有类型异常的`Exception`类型参数。

Example: Exception handling using `try` `catch` block

```
class Program
{
    static void Main(string[] args)
    {
        try
        {
            Console.WriteLine("Enter a number: ");

            var num = int.parse(Console.ReadLine());

            Console.WriteLine($"Squre of {num} is {num * num}");
        }
        catch(Exception ex)
        {
            Console.Write("Error info:" + ex.Message);
        }
        finally
        {
            Console.Write("Re-try with a different number.");
        }
    }
} 
```

## 异常过滤器

您可以使用具有不同异常类型参数的多个`catch`块。这被称为异常过滤器。当您想要以不同的方式处理不同类型的异常时，异常过滤器非常有用。

Example: Exception Filters

```
class Program
{
    static void Main(string[] args)
    {
        Console.Write("Please enter a number to divide 100: ");

        try
        {
            int num = int.Parse(Console.ReadLine());

            int result = 100 / num;

            Console.WriteLine("100 / {0} = {1}", num, result);
        }
        catch(DivideByZeroException ex)
        {
            Console.Write("Cannot divide by zero. Please try again.");
        }
        catch(InvalidOperationException ex)
        {
            Console.Write("Invalid operation. Please try again.");
        }
        catch(FormatException  ex)
        {
            Console.Write("Not a valid format. Please try again.");
        }
        catch(Exception  ex)
        {
            Console.Write("Error occurred! Please try again.");
        }
    }

} 
```

在上例中，我们指定了多个具有不同异常类型的`catch`块。我们可以根据错误向用户显示适当的消息，这样用户就不会再犯同样的错误。

*Note:**Multiple `catch` blocks with the same exception type are not allowed. A `catch` block with the base Exception type must be the last block.* *### 无效的捕获块

在同一个`try` -catch 语句中，不允许无参数的`catch`块和带有`Exception`参数的`catch`块，因为它们都做同样的事情。

Example: Invalid catch

```
try
{
    //code that may raise an exception
}
catch //cannot have both catch and catch(Exception ex)
{ 
    Console.WriteLine("Exception occurred");
}
catch(Exception ex) //cannot have both catch and catch(Exception ex)
{
    Console.WriteLine("Exception occurred");
} 
```

此外，无参数捕捉块`catch{ }`或通用捕捉块`catch(Exception ex){ }`必须是最后一个块。如果在`catch{ }`或`catch(Exception ex)`块之后有其他`catch`块，编译器会给出一个错误。

Example: Invalid catch

```
try
{
    //code that may raise an exception
}
catch
{ 
    // this catch block must be last block
}
catch (NullReferenceException nullEx)
{
    Console.WriteLine(nullEx.Message);
}
catch (InvalidCastException inEx)
{
    Console.WriteLine(inEx.Message);
} 
```

## 最后封锁

`finally`区块是可选区块，应该在`try`或捕捉区块之后。无论是否发生异常，都将始终执行`finally`块。`finally`块通常用于清理代码，例如处置非托管对象。

Example: finally Block

```
static void Main(string[] args)
{
    FileInfo file = null;

    try
    {
        Console.Write("Enter a file name to write: ");
        string fileName = Console.ReadLine();
        file = new FileInfo(fileName);
        file.AppendText("Hello World!")
    }
    catch(Exception ex)
    {
        Console.WriteLine("Error occurred: {0}", ex.Message );
    }
    finally
    {
        // clean up file object here;
        file = null;
    }
} 
```

*Note:**Multiple `finally` blocks are not allowed. Also, the `finally` block cannot have the return, continue, or break keywords. It doesn't let control to leave the `finally` block.* *## 嵌套试捕

C# 允许嵌套的 try-catch 块。当使用嵌套的 try-catch 块时，异常将在发生异常的`try`块之后的第一个匹配的`catch`块中被捕获。

Example: Nested try-catch

```
static void Main(string[] args)
{
    var divider = 0;

    try
    {
        try
        {
            var result = 100/divider;
        }
        catch
        {
            Console.WriteLine("Inner catch");
        }
    }
    catch
    {
        Console.WriteLine("Outer catch");
    }
} 
```

Output:<samp>Inner catch</samp>

在上面的例子中将执行一个内部`catch`块，因为它是处理所有异常类型的第一个`catch`块。

如果没有与引发的异常类型匹配的内部`catch`块，则控制将流向外部`catch`块，直到找到合适的异常过滤器。考虑下面的例子。

Example: Nested try-catch

```
static void Main(string[] args)
{
    var divider = 0;

    try
    {
        try
        {
            var result = 100/divider;
        }
        catch(NullReferenceException ex)
        {
            Console.WriteLine("Inner catch");
        }
    }
    catch
    {
        Console.WriteLine("Outer catch");
    }
} 
```

Output:<samp>Outer catch</samp>

在上例中，将引发类型为`DivideByZeroException`的异常。因为内`catch`块只处理`NullReferenceTypeException`，所以它将由外`catch`块处理。***