# C# -抛出关键字

> 原文：<https://www.tutorialsteacher.com/csharp/throw-csharp>

我们在上一节中已经看到了如何处理由 CLR 自动引发的异常。在这里，我们将看到如何手动引发异常。

可以使用 throw 关键字手动引发异常。从*异常*类派生的任何类型的异常都可以使用 throw 关键字引发。

Example: throw an exception

```
static void Main(string[] args)
{
    Student std = null;

    try
    {
        PrintStudentName(std);
    }
    catch(Exception ex)
    {
        Console.WriteLine(ex.Message );
    }                      

    Console.ReadKey();
}

private static void PrintStudentName( Student std)
{
    if (std  == null)
        throw new NullReferenceException("Student object is null.");

    Console.WriteLine(std.StudentName);
} 
```

Output:<samp>Student object is null.</samp>

在上面的示例中，如果 Student 对象为 null，PrintStudentName()方法将引发 NullReferenceException。

请注意，throw 使用 new 关键字创建任何有效异常类型的对象。throw 关键字不能与任何不是从异常类派生的其他类型一起使用。

## 重新引发异常

您也可以从 catch 块中重新抛出一个异常，传递给调用者，让调用者按照他们想要的方式处理它。以下示例重新引发异常。

Example: throw an exception

```
static void Main(string[] args)
{
    try
    {
        Method1();
    }
    catch(Exception ex)
    {
        Console.WriteLine(ex.StackTrace);
    }                      
}

static void Method1()
{
    try
    {
        Method2();
    }
    catch(Exception ex)
    {
        throw;
    } 
}

static void Method2()
{
    string str = null;
    try
    {
        Console.WriteLine(str[0]);
    }
    catch(Exception ex)
    {
        throw;
    } 
} 
```

在上面的示例中，Method2()中发生了异常。catch 块只使用 throw 关键字(而不是 throw e)抛出异常。这将在 Method1()中的 catch 块中处理，在那里它再次重新抛出相同的异常，最后在 Main()方法中处理。该异常的堆栈跟踪将为您提供该异常发生的完整细节。

如果您使用异常参数重新引发异常，那么它将不会保留原始异常并创建新的异常。下面的示例演示了这一点。

Example: throw an exception

```
static void Main(string[] args)
{
    try
    {
        Method1();
    }
    catch(Exception ex)
    {
        Console.WriteLine(ex.StackTrace);
    }                      
}

static void Method1()
{
    try
    {
        Method2();
    }
    catch(Exception ex)
    {
        throw ex;
    } 
}

static void Method2()
{
    string str = null;
    try
    {
        Console.WriteLine(str[0]);
    }
    catch(Exception ex)
    {
        throw;
    } 
} 
```

在上面的示例中，Main()方法中捕获的异常将显示 Method1 和 Main 方法的堆栈跟踪。它不会在堆栈跟踪中显示方法 1，因为我们使用`throw ex`在方法 1()中重新抛出异常。 所以，千万不要用`throw <exception parameter>`抛出异常。

在下一节中学习如何创建自定义异常类型。