# JavaScript 中的错误处理

> 原文：<https://www.tutorialsteacher.com/javascript/javascript-error-handling>

JavaScript 是一种松散类型的语言。它不会给出编译时错误。所以有时候你会因为访问一个未定义的变量或者调用一个未定义的函数而得到一个运行时错误。

![](img/751bca76a769f8ad315ebee3fdf7d98e.png)  try catch block does not handle syntax errors.

JavaScript 提供了错误处理机制，使用 try-catch-finally 块来捕获运行时错误，类似于 Java 或 C# 等其他语言。

Syntax:

```
try
{
    // code that may throw an error
}
catch(ex)
{
    // code to be executed if an error occurs
}
finally{
    // code to be executed regardless of an error occurs or not
}

```

*   **try:** 包装可能在 try 块中抛出错误的可疑代码。
*   **catch:** 当错误发生时，编写代码在 catch 块中做一些事情。catch 块可以有给你错误信息的参数。通常，catch 块用于记录错误或向用户显示特定消息。
*   **finally:**finally 块中的代码将总是被执行，而不管错误的发生。finally 块可用于完成剩余的任务或重置在 try 块中发生错误之前可能已更改的变量。

让我们看看简单的错误处理示例。

Example: Error Handling in JS

```
try
{
    var result  =  Sum(10, 20); // Sum is not defined yet
}
catch(ex)
{
    document.getElementById("errorMessage").innerHTML = ex;
} 
```

在上面的例子中，我们调用的是 Sum 函数，它还没有定义。因此，try block 将抛出一个错误，该错误将由 catch block 处理。Ex 包括可以显示的错误信息。

不管发生什么，finally 块都会执行。

Example: finally Block

```
try
{
     var result  =  Sum(10, 20); // Sum is not defined yet
}
catch(ex)
{
    document.getElementById("errorMessage").innerHTML = ex;
}
finally{
    document.getElementById("message").innerHTML = "finally block executed";
} 
```

## 扔

使用 throw 关键字引发自定义错误。

Example: throw Error

```
try
{
    throw "Error occurred";
}
catch(ex)
{
    alert(ex);
} 
```

有关错误的更多信息，可以使用 JavaScript 对象。

Example: throw error with error info

```
try 
{
    throw {
        number: 101,
        message: "Error occurred"
    };
}
catch (ex) {
    alert(ex.number + "- " + ex.message);
} 
```